Workbook

Sheet CNAE
A1: Empreses actives
A2: Resultats per comunitats autònomes
A4: Empreses per CCAA, activitat principal (grups CNAE 2009) i estrat d'assalariats (antiga estratificació).
A5: Unitats: Empreses
B7: Total | C7: Porcentaje | D7: Total PYMES CAT | E7: Sin asalariados | F7: De 1 a 2 | G7: De 3 a 5 | H7: De 6 a 9 | I7: De 10 a 19 | J7: De 20 a 49 | K7: De 50 a 99 | L7: De 100 a 199
B8: 2020 | C8: 2020 | D8: 2020 | E8: 2020 | F8: 2020 | G8: 2020 | H8: 2020 | I8: 2020 | J8: 2020 | K8: 2020 | L8: 2020
A9: Total Nacional
A10: Total CNAE | B10: 3404428 | E10: 1912010 | F10: 907192 | G10: 305986 | H10: 125472 | I10: 81298 | J10: 46101 | K10: 13275 | L10: 6906
A11: 05 Extracción de antracita, hulla y lignito | B11: 58 | E11: 43 | F11: 5 | G11: 1 | H11: 2 | I11: 3 | J11: 0 | K11: 3 | L11: 0
A12: 051 Extracción de antracita y hulla | B12: 55 | E12: 41 | F12: 4 | G12: 1 | H12: 2 | I12: 3 | J12: 0 | K12: 3 | L12: 0
A13: 052 Extracción de lignito | B13: 3 | E13: 2 | F13: 1 | G13: 0 | H13: 0 | I13: 0 | J13: 0 | K13: 0 | L13: 0
A14: 06 Extracción de crudo de petróleo y gas natural | B14: 8 | E14: 2 | F14: 4 | G14: 1 | H14: 0 | I14: 0 | J14: 1 | K14: 0 | L14: 0
A15: 061 Extracción de crudo de petróleo | B15: 6 | E15: 1 | F15: 4 | G15: 1 | H15: 0 | I15: 0 | J15: 0 | K15: 0 | L15: 0
A16: 062 Extracción de gas natural | B16: 2 | E16: 1 | F16: 0 | G16: 0 | H16: 0 | I16: 0 | J16: 1 | K16: 0 | L16: 0
A17: 07 Extracción de minerales metálicos | B17: 68 | E17: 34 | F17: 12 | G17: 6 | H17: 2 | I17: 4 | J17: 2 | K17: 4 | L17: 0
A18: 071 Extracción de minerales de hierro | B18: 19 | E18: 11 | F18: 3 | G18: 3 | H18: 1 | I18: 0 | J18: 1 | K18: 0 | L18: 0
A19: 072 Extracción de minerales metálicos no férreos | B19: 49 | E19: 23 | F19: 9 | G19: 3 | H19: 1 | I19: 4 | J19: 1 | K19: 4 | L19: 0
A20: 08 Otras industrias extractivas | B20: 1768 | E20: 556 | F20: 427 | G20: 244 | H20: 181 | I20: 207 | J20: 120 | K20: 25 | L20: 4
A21: 081 Extracción de piedra, arena y arcilla | B21: 1607 | E21: 499 | F21: 389 | G21: 226 | H21: 167 | I21: 193 | J21: 111 | K21: 19 | L21: 3
... A343: 960 Otros servicios personales | B343: 137801 | E343: 75338 | F343: 47259 | G343: 10548 | H343: 3297 | I343: 830 | J343: 377 | K343: 94 | L343: 30
A344: 09 Cataluña
A345: Total CNAE | B345: 629876 | C345: =D345/$D$345 -> 1 | D345: =SUM(E345:L345) -> 628520 | E345: 365634 | F345: 158687 | G345: 53214 | H345: 22558 | I345: 15229 | J345: 8947 | K345: 2774 | L345: 1477
A346: 05 Extracción de antracita, hulla y lignito | B346: 5 | C346: =D346/$D$345 -> 7.9551963e-06 | D346: =SUM(E346:L346) -> 5 | E346: 5 | F346: 0 | G346: 0 | H346: 0 | I346: 0 | J346: 0 | K346: 0 | L346: 0
A347: 051 Extracción de antracita y hulla | B347: 5 | C347: =D347/$D$345 -> 7.9551963e-06 | D347: =SUM(E347:L347) -> 5 | E347: 5 | F347: 0 | G347: 0 | H347: 0 | I347: 0 | J347: 0 | K347: 0 | L347: 0
A348: 052 Extracción de lignito | B348: 0 | C348: =D348/$D$345 -> 0 | D348: =SUM(E348:L348) -> 0 | E348: 0 | F348: 0 | G348: 0 | H348: 0 | I348: 0 | J348: 0 | K348: 0 | L348: 0
A349: 06 Extracción de crudo de petróleo y gas natural | B349: 0 | C349: =D349/$D$345 -> 0 | D349: =SUM(E349:L349) -> 0 | E349: 0 | F349: 0 | G349: 0 | H349: 0 | I349: 0 | J349: 0 | K349: 0 | L349: 0
A350: 061 Extracción de crudo de petróleo | B350: 0 | C350: =D350/$D$345 -> 0 | D350: =SUM(E350:L350) -> 0 | E350: 0 | F350: 0 | G350: 0 | H350: 0 | I350: 0 | J350: 0 | K350: 0 | L350: 0
A351: 062 Extracción de gas natural | B351: 0 | C351: =D351/$D$345 -> 0 | D351: =SUM(E351:L351) -> 0 | E351: 0 | F351: 0 | G351: 0 | H351: 0 | I351: 0 | J351: 0 | K351: 0 | L351: 0
A352: 07 Extracción de minerales metálicos | B352: 2 | C352: =D352/$D$345 -> 3.1820785e-06 | D352: =SUM(E352:L352) -> 2 | E352: 0 | F352: 1 | G352: 1 | H352: 0 | I352: 0 | J352: 0 | K352: 0 | L352: 0
A353: 071 Extracción de minerales de hierro | B353: 1 | C353: =D353/$D$345 -> 1.5910393e-06 | D353: =SUM(E353:L353) -> 1 | E353: 0 | F353: 1 | G353: 0 | H353: 0 | I353: 0 | J353: 0 | K353: 0 | L353: 0
A354: 072 Extracción de minerales metálicos no férreos | B354: 1 | C354: =D354/$D$345 -> 1.5910393e-06 | D354: =SUM(E354:L354) -> 1 | E354: 0 | F354: 0 | G354: 1 | H354: 0 | I354: 0 | J354: 0 | K354: 0 | L354: 0
A355: 08 Otras industrias extractivas | B355: 154 | C355: =D355/$D$345 -> 0.00024183797 | D355: =SUM(E355:L355) -> 152 | E355: 53 | F355: 31 | G355: 19 | H355: 8 | I355: 27 | J355: 11 | K355: 3 | L355: 0
A356: 081 Extracción de piedra, arena y arcilla | B356: 141 | C356: =D356/$D$345 -> 0.00022433654 | D356: =SUM(E356:L356) -> 141 | E356: 49 | F356: 29 | G356: 19 | H356: 8 | I356: 23 | J356: 11 | K356: 2 | L356: 0
... A678: 960 Otros servicios personales | B678: 23510 | C678: =D678/$D$345 -> 0.037395787 | D678: =SUM(E678:L678) -> 23504 | E678: 12316 | F678: 8516 | G678: 1823 | H678: 597 | I678: 144 | J678: 76 | K678: 20 | L678: 12
A681: Notas:
A683: Fuente:

Sheet Crèdits
A1: Crèdits © Generalitat de Catalunya Departament d’Acció Climàtica, Alimentació i Agenda Rural Primera edició, gener de 2024 AUTORS Ramon Scholl1, Oliver Canosa Daroca1, Oriol Lafarga Amorós1, Eduardo Macon Bayarri1, Clara Sánchez Cerdà1 COORDINACIÓ Maria José Sarrias Galcerán2, Virginia Ferrer-Vidal Cortella2 1 TECNOAMBIENTE 2 Direcció general de Canvi Climàtic i Qualitat Ambiental Departament d’Acció Climàtica, Alimentació i Agenda Rural

Sheet Mapa de materialitat
B2: Mapa de materialitat Ambiental, Social i de Governança (ASG) per a la PIME per sector econòmic | N2: Medi ambient | O2: Eficiència energètica i energies renovables | P2: Emissions de GEH | Q2: Impactes físics del canvi climàtic | R2: Gestió sostenible de l'aigua | S2: Gestió de residus i materials perillosos | T2: Biodiversitat i ecosistemes | U2: Disseny del producte i gestió del cicle de vida | V2: Oportunitats de tecnologies/aplicacions sostenibles | W2: Subministrament de matèries primeres / productes venuts | X2: Qualitat de l'aire | Y2: Seguretat química | Z2: Materials d'embalatge | AA2: Social | AB2: Seguretat i salut laboral | AC2: Desenvolupament del capital humà | AD2: Ciberseguretat | AE2: Protecció de dades | AF2: Seguretat i qualitat del producte | AG2: Benestar del client | AH2: Condicions laborals | AI2: Pràctiques de venda i etiquetatge | AJ2: Compromís dels empleats, diversitat i inclusió | AK2: Oportunitats de nutrició i salut | AL2: Estàndards laborals en la cadena de valor | AM2: Assequibilitat i accés als serveis | AN2: Relacions amb les comunitats afectades | AO2: Governança | AP2: Bon govern | AQ2: Competència responsable | AR2: Gestió de riscos d'incidents crítics | AS2: Gestió de riscos sistèmics | AT2: Gestió de la cadena de subministrament | AU2: Resiliència del model de negoci
C3: Total | D3: Porcentaje | E3: Total PIMES CAT | F3: Sin asalariados | G3: De 1 a 2 | H3: De 3 a 5 | I3: De 6 a 9 | J3: De 10 a 19 | K3: De 20 a 49 | L3: De 50 a 99 | M3: De 100 a 199
B4: Indústria alimentària i de begudes | D4: 0.006 | E4: 3750
B5: Indústria de la moda i tèxtil | D5: 0.0067 | E5: 4225
B6: Indústria de fusta i paper | D6: 0.0034 | E6: 2138
B7: Altres indústries manufactureres | D7: 0.025 | E7: 15698
B8: Indústries de serveis d'aigua i tractament de residus | D8: 0.0014 | E8: 894
B9: Construcció | C9: 40714 | D9: =E9/#REF! -> #REF! | E9: =SUM(F9:M9) -> 40705 | F9: 26920 | G9: 8810 | H9: 2711 | I9: 1135 | J9: 725 | K9: 321 | L9: 67 | M9: 16
B10: Serveis especialistes de construcció | C10: 33298 | D10: =E10/#REF! -> #REF! | E10: =SUM(F10:M10) -> 33287 | F10: 18164 | G10: 9181 | H10: 2998 | I10: 1330 | J10: 985 | K10: 503 | L10: 97 | M10: 29
B11: Serveis tècnics d'arquitectura i enginyeria; assaigs i anàlisis tècniques | C11: 21224 | D11: =E11/#REF! -> #REF! | E11: =SUM(F11:M11) -> 21207 | F11: 15419 | G11: 4021 | H11: 874 | I11: 395 | J11: 336 | K11: 109 | L11: 37 | M11: 16
B12: Venda i reparació de vehicles de motor i motocicletes | C12: 10707 | D12: =E12/#REF! -> #REF! | E12: =SUM(F12:M12) -> 10690 | F12: 4440 | G12: 3957 | H12: 1260 | I12: 459 | J12: 335 | K12: 157 | L12: 44 | M12: 38
B13: Comerç a l'engròs i intermediaris del comerç, excepte de vehicles de motor i motocicletes | C13: 41693 | D13: =E13/#REF! -> #REF! | E13: =SUM(F13:M13) -> 41591 | F13: 21277 | G13: 11024 | H13: 3710 | I13: 2561 | J13: 1514 | K13: 1006 | L13: 346 | M13: 153
B14: Comerç al detall, excepte de vehicles de motor i motocicletes | C14: 69185 | D14: =E14/#REF! -> #REF! | E14: =SUM(F14:M14) -> 69116 | F14: 31160 | G14: 25048 | H14: 9314 | I14: 2241 | J14: 759 | K14: 438 | L14: 103 | M14: 53
B15: Transport terrestre | C15: 33561 | D15: =E15/#REF! -> #REF! | E15: =SUM(F15:M15) -> 33529 | F15: 23147 | G15: 7221 | H15: 1542 | I15: 721 | J15: 493 | K15: 316 | L15: 60 | M15: 29
B16: Serveis d'allotjaments i serveis de menjars i begudes (hoteleria) | C16: 40509 | D16: =E16/#REF! -> #REF! | E16: =SUM(F16:M16) -> 40468 | F16: 12343 | G16: 15829 | H16: 8212 | I16: 2365 | J16: 1023 | K16: 534 | L16: 108 | M16: 54
B17: Programació, consultoria i altres activitats relacionades amb la informàtica | C17: 9320 | D17: =E17/#REF! -> #REF! | E17: =SUM(F17:M17) -> 9290 | F17: 5921 | G17: 1850 | H17: 554 | I17: 326 | J17: 339 | K17: 199 | L17: 59 | M17: 42
B18: Activitats auxiliars als serveis financers i les assegurances | C18: 12372 | D18: =E18/#REF! -> #REF! | E18: =SUM(F18:M18) -> 12369 | F18: 9464 | G18: 2326 | H18: 391 | I18: 96 | J18: 46 | K18: 30 | L18: 11 | M18: 5
B19: Activitats jurídiques i de comptabilitat | C19: 25592 | D19: =E19/#REF! -> #REF! | E19: =SUM(F19:M19) -> 25578 | F19: 15593 | G19: 6597 | H19: 1866 | I19: 809 | J19: 579 | K19: 108 | L19: 21 | M19: 5
B20: Activitats de les seus centrals; activitats de consultoria de gestió empresarial | C20: 4762 | D20: =E20/#REF! -> #REF! | E20: =SUM(F20:M20) -> 4741 | F20: 1975 | G20: 1725 | H20: 485 | I20: 247 | J20: 178 | K20: 83 | L20: 33 | M20: 15
... B27: Activitats sanitàries | C27: 33537 | D27: =E27/#REF! -> #REF! | E27: =SUM(F27:M27) -> 33455 | F27: 25363 | G27: 5289 | H27: 1610 | I27: 592 | J27: 339 | K27: 159 | L27: 69 | M27: 34

Sheet AUTO
B1: Mediambiental | C1: Eficiència energètica i energies renovables | D1: Emissions de GEH | E1: Impactes físics del canvi climàtic | F1: Gestió sostenible de l'aigua | G1: Gestió de residus i materials perillosos | H1: Biodiversitat i ecosistemes | I1: Disseny del producte i gestió del cicle de vida | J1: Oportunitats de tecnologies / aplicacions sostenibles | K1: Subministrament de matèries primeres / productes venuts | L1: Qualitat de l'aire | M1: Seguretat química | N1: Materials d'embalatge | O1: Oportunitats de construcció sostenible | P1: Social | Q1: Salut i seguretat laboral | R1: Desenvolupament del capital humà | S1: Ciberseguretat | T1: Protecció de dades | U1: Seguretat i qualitat del producte | V1: Benestar del client | W1: Condicions laborals | X1: Practiques de venda i etiquetatge | Y1: Compromís dels empleats, diversitat i inclusió | Z1: Oportunitats de nutrició i salut | AA1: Estàndards de treball en la cadena de valor | AB1: Accés i assequibilitat | AC1: Relacions amb les comunitats afectades | AD1: Governança | AE1: Bon govern | AF1: Competència responsable | AG1: Gestió de riscos d'incidents critics | AH1: Gestió de riscos sistèmics | AI1: Gestió de la cadena de subministrament | AJ1: Resiliència del model de negoci
B2: Descripció | C2: L'eficiència energètica i les energies renovables se centren a disminuir el consum energètic respecte de la producció. Les empreses amb una alta eficiència energètica són més sostenibles ambientalment i econòmicament, ja que requereixen menys recursos (combustibles, electricitat, matèries primeres, etc.) per generar el mateix volum d'ingressos que una de menys eficient. | D2: Les emissions de gasos amb efecte d'hivernacle i les energies renovables són categories estretament vinculades amb el canvi climàtic. Les empreses amb una major petjada de carboni contribueixen en major mesura al canvi climàtic. Reduir els impactes relacionats amb aquest tema requereix una reducció de la petjada de carboni de l'empresa. Això requereix una transició envers fonts d'energia renovables i la implementació d'estratègies per assolir emissions netes zero. | E2: Els impactes físics del canvi climàtic són aquells que experimenta, experimentarà o ja ha experimentat l'empresa vinculats a modificacions en variables climàtiques. Per exemple, la manca d'aigua a causa d'una sequera prolongada, danys provocats per inundacions causades per una tempesta especialment forta, pedregades o els costos en què l'empresa ha d'incórrer per adaptar-se a un clima canviant. | F2: La gestió sostenible de l'aigua tracta d'assegurar que el consum i ús d'aquesta aigua per part de l'empresa estiguin alineats amb la capacitat de recuperar-se de l'ecosistema i no generin impactes negatius. Les necessitats de consumir aigua estan lligades al sector i a la ubicació de la planta. És important destacar que les empreses amb operacions en zones amb estrès hídric caldrà que avaluïn com fer una gestió sostenible dels recursos hídrics. Això inclou reduir el consum d'aigua, millorar la captura i reutilització de les aigües grises i millorar el tractament d'aigües residuals, entre d'altres. | G2: La gestió de residus perillosos i no perillosos és un àmbit en constant evolució normativa. L'adequada gestió de residus i materials perillosos és clau per reduir la contaminació causada per l'empresa o els productes que posa al mercat. Optimitzar el disseny i la producció i treballar paral·lelament a millorar la gestió de residus és clau per transicionar envers una economia circular que redueixi la necessitat d'explotació de nous recursos naturals. Per tant, les empreses que gestionen els seus residus i eviten la seva generació són més sostenibles i estan més alineades amb els principis de l'economia circular. | H2: Aquesta categoria se centra en els impactes de les operacions o els actius d'una empresa sobre ecosistemes i la seva biodiversitat. Les activitats amb potencials impactes significatius són aquelles vinculades amb canvis en l'ús del sòl per a exploració/explotació de recursos naturals, construcció, agricultura extensiva, etc. Els impactes poden produir pèrdua de biodiversitat, destrucció d'hàbitats, deforestació i pèrdua de serveis ecosistèmics bàsics. Les empreses haurien d'avaluar les seves dependències i impactes sobre el capital natural (natura), mitigar els riscos associats i fomentar un impacte positiu en totes les fases de la cadena de valor de l'empresa. | I2: El disseny dels productes i els seus cicles de vida són molt importants per gestionar l'impacte mediambiental de l'empresa. L'ecodisseny pot facilitar la reparació i el manteniment del producte i millorar-ne la tria dels materials més adequats i la reuitilització. Un correcte ecodisseny assegura una reducció dels impactes en tot el cicle de vida del producte. Les empreses que tenen en compte els impactes durant tot el cicle de vida permeten reduir l'impacte total del producte o servei en l'ús de materials, disseny industrial, producció i gestió de residus. D'aquesta manera, les empreses s'adapten als esquemes de responsabilitat ampliada del productor o futures normatives enfocades a la circularitat de l'economia. | J2: Les oportunitats de tecnologies/aplicacions sostenibles són rellevants en aquells sectors on hi ha tecnologies descarbonitzades que poden ajudar l'empresa a assolir els seus objectius de reducció d'emissons. Per exemple, la instal·lació de renovables en el sector d'energia o les aplicacions de tecnologies verdes a la construcció de nous edificis per al sector de l'edificació són oportunitats importants per diferenciar-se de la competència en termes de sostenibilitat. La sostenibilitat planteja moltes oportunitats que asseguren una reducció de les despeses de l'empresa a llarg termini. | K2: El subministrament de matèries primeres és un tema crucial per a la sostenibilitat d'aquells sectors molt intensius en materials. Aquí les empreses haurien d'avaluar oportunitats per a una adquisició de matèries de manera sostenible amb proveïdors confiables i certificats i estratègies de recuperació de material que es pugui recuperar com a matèria primera. Aquest tema pot ser important tant per a empreses que adquireixen matèries primeres com per a empreses que adquireixen prefabricats o productes. Un exemple és la cadena de subministrament d'empreses alimentàries, on és obligatori poder demostrar que el producte utilitzat no prové de zones amb alta deforestació. | L2: Les emissions de contaminants com el diòxid de sofre (SOx), el diòxid de nitrogen (NOx) i els Compostos Orgànics Volàtils (VOC), entre d'altres, poden tenir un impacte significatiu sobre la qualitat de l'aire. Una mala qualitat de l'aire pot tenir efectes negatius tant sobre el medi ambient com sobre la salut de les comunitats afectades. Per tant, les empreses que duen a terme operacions que produeixen emissions a l'aire han d'avaluar el seu impacte sobre la qualitat de l'aire mitjançant controls regulars duts a terme per l'autoritat ambiental competent. Les empreses podrien considerar la instal·lació de filtres i altres mesures destinades a reduir les emissions de contaminants atmosfèrics. | M2: Garantir la seguretat química és de gran importància per preservar els ecosistemes i protegir les comunitats properes a instal·lacions que empren substàncies químiques perilloses. Les empreses que comercialitzen productes que contenen substàncies químiques perilloses susceptibles d'entrar en contacte amb l'entorn natural o els usuaris d'aquests productes és essencial que prenguin totes les mesures necessàries per prevenir aquesta situació. Millorar la seguretat química pot implicar la recerca d'alternatives de materials per a l'ús en els seus productes, dissenyar productes de manera segura per prevenir fuites de substàncies i elaborar un pla de gestió de residus al final del cicle de vida del producte. | N2: Els materials d'embalatge son part del dia a dia i en certs casos acaben a la natura. És important que el productor faci un exercici d'ecodisseny que asseguri el mínim ús de material i la màxima reciclabilitat. | O2: Les oportunitats de tecnologies/aplicacions sostenibles són rellevants per als sectors on hi ha tecnologies verdes o aplicacions sostenibles que es podrien implementar per afavorir la sostenibilitat de l'empresa. Per exemple, la instal·lació de capacitat de renovables en el sector de l'energia o les aplicacions de tecnologies verdes en la construcció de nous edificis per al sector de l'edificació són oportunitats importants per diferenciar-se de la competència en termes de sostenibilitat. | Q2: La salut i seguretat laboral hauria de ser una prioritat fonamental en qualsevol empresa. Totes les empreses han d'assegurar-se de proporcionar un entorn de treball segur i saludable per als seus empleats. Això és especialment crucial en aquelles empreses que duen a terme operacions perilloses o tenen el potencial d'afectar adversament la salut dels seus treballadors. Una de les mesures clau per assegurar la salut i seguretat dels empleats és designar un/a responsable de salut i seguretat la funció principal del qual consisteix a avaluar els riscos per als empleats i implementar mesures de mitigació corresponents. | R2: El desenvolupament del capital humà pot ser un factor important per a empreses en sectors que requereixen coneixements o habilitats específiques. Les empreses que no inverteixen en el desenvolupament dels seus empleats poden perdre competitivitat en el mercat laboral, la qual cosa pot afectar la seva capacitat d'atreure i mantenir personal capacitat. Per assegurar la sostenibilitat social i econòmica en el futur, l'empresa pot oferir oportunitats de creixement al seu personal. En la mateixa línia, per mantenir una posició competitiva al mercat, les empreses han d'invertir en la formació i educació dels seus empleats. | S2: La ciberseguretat tracta sobre la seguretat dels sistemes informàtics de les empreses. Aquests sistemes poden contenir informació crucial per a les operacions de l'empresa i/o dels seus clients, per la qual cosa és important comptar amb un bon nivell de protecció. Les empreses poden millorar la seva seguretat si assignen un responsable de ciberseguretat al departament d'IT. Addicionalment, podrien dur a terme proves de seguretat periòdiques i establir protocols per contenir qualsevol risc digital, entre d'altres. | T2: La protecció de dades se centra en l'emmagatzematge i la gestió segura de les dades de clients, empleats i altres grups d'interès. És important respectar el RGPD (UE 2016/679) que estableix els requisits de la protecció de dades a la UE. A més, és important que només persones assignades tinguin accés a les dades emmagatzemades per l'empresa i sempre respectant-ne la privacitat. Per assegurar la protecció, les empreses poden establir una política de protecció de dades, assignar una persona reponsable i assegurar que els sistemes informàtics són adequats per protegir-los. | U2: La seguretat i qualitat són aspectes importants del producte, no només des d'una perspectiva econòmica, sinó també des d'una perspectiva de sostenibilitat. Falles de seguretat i/o qualitat del producte poden afectar negativament la salut o la seguretat dels usuaris, la qual cosa pot produir una varietat de riscos tant per a la reputació de l'empresa com legals. Algunes de les mesures que les empreses poden prendre per gestionar aquests riscos són dur a terme proves de productes i gestionar el contingut, els ingredients i els químics utilitzats en el producte. | V2: Alguns productes poden tenir un impacte sobre el benestar a llarg termini dels clients. Això no es refereix a riscos de seguretat immediats, sinó a efectes que es desenvolupen amb el temps. Exemples d'aquests tipus d'impacte inclouen l'ús d'antibiòtics en la producció de carn, efectes negatius sobre la salut causats per aliments amb alt contingut de sal, sucre i greix i l'ús de substàncies que poden tenir efectes perjudicials després de llargs períodes d'exposició. Algunes mesures per protegir el benestar dels clients inclouen la implementació de mètodes de producció segurs i l'adaptació de receptes de productes per reduir la quantitat d'ingredients perjudicials. | W2: Per tenir una bona consideració social i contribuir a una societat més justa, les empreses haurien d'oferir bones condicions laborals als seus empleats. Això no es limita al compliment dels drets humans; també inclou drets laborals, remuneració justa, horaris dignes, pagament d'hores extres, etc. Addicionalment, per anar més enllà dels compliments legals, les empreses poden oferir oportunitats de creixement, dret a desconnexió digital, posicions híbrides o en remot i altres mesures de conciliació per promoure l'equilibri entre la vida laboral i la personal. | X2: És essencial mantenir Bones Pràctiques en la venda i l'etiquetatge de productes per prevenir qualsevol pràctica enganyosa. Les pràctiques enganyoses poden portar els consumidors a triar un producte que no s'ajusti a les seves necessitats o requeriments. Per tant, per garantir Bones Pràctiques en la venda i l'etiquetatge, una empresa ha de gestionar la transparència de la informació relacionada amb els seus productes, operacions i cadenes de valor. A més, és fonamental proporcionar informació precisa i rellevant sobre els productes, sense ocultar desavantatges o altres tipus d'informació d'interès. | Y2: El compromís dels empleats i la promoció de la diversitat i inclusió a l'empresa són temes socials de gran rellevància. Aquests aspectes asseguren que la força laboral sigui diversa i que s'ofereixin oportunitats sense discriminació, la qual cosa permet la inclusió de membres de les comunitats locals i els consumidors dels productes de l'empresa. Per fomentar el compromís, la diversitat i la inclusió en l'empresa, és fonamental establir polítiques antidiscriminatòries en el procés de reclutament i promoure una cultura corporativa inclusiva. | Z2: Particularment en la indústria alimentària i de begudes, les oportunitats relacionades amb la nutrició i la salut són fonamentals per proporcionar productes de més qualitat als consumidors. Des d'una perspectiva de sostenibilitat social, és crucial que les empreses aprofitin les oportunitats per oferir productes amb un major valor nutricional i beneficis per a la salut dels consumidors. Aquelles empreses que aprofiten aquestes oportunitats poden destacar en el mercat, la qual cosa al seu torn contribueix a la seva sostenibilitat econòmica. | AA2: És crucial mantenir alts estàndards laborals i condicions de treball dignes per a tots els empleats en la cadena de valor. L'empresa s'ha d'assegurar que tots els seus proveïdors respectin els drets laborals i humans, la qual cosa inclou garantir una remuneració justa, horaris laborals adequats i la prohibició del treball forçós i el treball infantil. Per assegurar condicions laborals acceptables en tota la cadena de valor, l'empresa pot requerir el compliment d'un codi de conducta per part dels seus proveïdors i dur a terme auditories en alguns d'ells per verificar-ne el compliment. | AB2: L'accés i l'assequibilitat, especialment de productes i serveis bàsics, és important per a la igualtat d'oportunitats. Les empreses haurien de gestionar els preus i costos de manera responsable per oferir els productes i serveis (bàsics) a un preu assequible per a totes les persones que ho necessitin. Addicionalment, s'hauria d'avaluar l'accessibilitat de productes, serveis i edificis a totes les persones, incloent-hi les persones amb discapacitat, i prendre mesures per assegurar l'accessibilitat universal. | AC2: Les organitzacions tenen un impacte sobre les comunitats on operen, tant a través d'impactes físics com a través de la interacció amb els membres d'aquestes comunitats que treballen a l'empresa. Per tant, és fonamental establir relacions sòlides i respectuoses envers les comunitats afectades a través d'un diàleg que permeti comprendre i abordar els impactes negatius generats per les operacions. Algunes eines que es poden utilitzar per mantenir relacions efectives amb les comunitats inclouen la realització de reunions periòdiques amb representants de la comunitat, la incorporació de membres de la societat a l'empresa i el manteniment d'una comunicació constant amb organitzacions locals. | AE2: El bon govern és un tema ampli, enfocat en la gestió responsable i ètica de l'organització en general. L'acompliment de bon govern està vinculat als codis ètics de l'empresa, l'estructura de la propietat i el control de l'empresa, la junta directiva (i la seva remuneració), una comptabilitat transparent, la política fiscal i la transparència. | AF2: La competència responsable és crucial per combatre els monopolis i el lobbisme en les indústries. El seu objectiu principal és prevenir preus excessius, baixa qualitat en productes i serveis i d'altres irregularitats en el mercat. És essencial que qualsevol col·laboració entre empreses es realitzi de manera responsable i amb el propòsit de millorar els productes i serveis oferts als clients. | AG2: La gestió de riscos d'incidents crítics és rellevant per a organitzacions que duen a terme activitats o operacions perilloses. En aquest context, les organitzacions que identifiquen, comprenen, prevenen i minimitzen els riscos d'incidents que podrien ocórrer aconseguiran un millor acompliment en termes de sostenibilitat en la seva governança corporativa. Les empreses poden millorar el seu rendiment mitjançant la promoció d'una cultura de seguretat, la implementació de tecnologies que ajudin en la gestió de riscos, la realització d'anàlisi de probabilitat i impacte dels riscos i l'aplicació de mesures per mitigar aquests riscos, entre altres accions. | AH2: La gestió de riscos sistèmics s'enfoca a la contribució d'una empresa pel que fa als riscos sistèmics que amenacen els sistemes econòmics, socials, ambientals i tecnològics dels quals la societat depèn. Exemples d'aquests riscos inclouen el consum excessiu d'aigua per part d'una empresa que opera en una zona que ja pateix estrès hídric. Per millorar la seva gestió de la sostenibilitat, l'organització pot avaluar els seus impactes i aplicar plans i mesures de mitigació, entre altres accions. | AI2: La gestió de les cadenes de subministrament és essencial per supervisar les externalitats ambientals i socials generades per les activitats dels proveïdors. Dins de les cadenes de valor, poden sorgir problemes relacionats amb la responsabilitat ambiental, els drets humans, les condicions laborals, l'ètica i la corrupció, entre altres aspectes. La gestió de les cadenes de subministrament pot implicar l'avaluació, selecció, seguiment i compromís amb els proveïdors amb l'objectiu de reduir i mitigar els impactes mediambientals i socials. | AJ2: La resiliència del model de negoci fa referència a la capacitat de l'empresa d'adaptar-se als canvis relacionats amb les transicions ASG (mediambientals, socials i de bon govern). Això inclou la capacitat de mitigar riscos (com els reputacionals, legals i físics) i aprofitar les oportunitats que presenten els possibles nous mercats i productes i la diferenciació basada en la sostenibilitat. Les empreses més resilients compten amb sistemes de gestió de la sostenibilitat que identifiquen, avaluen i responen als riscos i les oportunitats potencials.
B3: Indicadors | AE3: - Composició de la junta directiva - % de membres independents dins la junta directiva - Existència de canals de denúncies i protecció de les parts interessades involucrades - % d'alts càrrecs investigats o condemnats - Compliment de codis (ètic, conducta, etc.) i normatives - % dels empleats (incloent-hi junta directiva) amb remuneració basada en la consecució d'objectius de sostenibilitat. - Auditories i certificacions independents | AI3: - % de proveïdors principals (valor de contractes) avaluats en temes de sostenibilitat - Petjada de carboni de la cadena de subministrament - % d'energia renovable en la cadena de subministrament - Reducció de residus i reciclatge dins de la cadena de subministrament (ecodisseny, embalatge, programes de retorn (take-back)) - Certificació mediambiental i social de proveïdors - Compliment dels drets laborals - Avaluació del cicle de vida dels productes
AT39: Alta relevancia
AT40: Relevancia significativa
AT41: Relevancia elevada
AT42: Sin especial relevancia

Sheet Fuentes
A1: Industria | B1: Tema | C1: Fuente | D1: URL
A2: Construcción | B2: Matrice de materialidad | C2: SASB: Home Builders | D2: https://sasb.org/standards/materiality-finder/find/?industry%5B0%5D=IF-EN
A3: Construcción | B3: Matrice de materialidad | C3: MSCI: Real Estate Development | D3: https://www.msci.com/our-solutions/esg-investing/esg-industry-materiality-map
A4: Servicios Técnicos de arquitectura e ingeniería | B4: Matrice de materialidad | C4: SASB: Engineering & Construction Services | D4: https://sasb.org/standards/materiality-finder/find/?industry%5B0%5D=IF-HB
A5: Servicios Técnicos de arquitectura e ingeniería | B5: Matrice de materialidad | C5: MSCI: Real Estate Services | D5: https://www.msci.com/our-solutions/esg-investing/esg-industry-materiality-map
A6: Publicidad (Marketing) | B6: Matrice de materialidad | C6: SASB: Advertising & Marketing | D6: https://sasb.org/standards/materiality-finder/find/?industry%5B0%5D=SV-AD
A7: Publicidad (Marketing) | B7: Matrice de materialidad | C7: SASB: Professional and Commercial Services | D7: https://sasb.org/standards/materiality-finder/find/?industry%5B0%5D=SV-PS
A8: Publicidad (Marketing) | B8: Matrice de materialidad | C8: MSCI: Advertising | D8: https://www.msci.com/our-solutions/esg-investing/esg-industry-materiality-map
A9: Hostelería | B9: Matrice de materialidad | C9: SASB: Restaurants | D9: https://sasb.org/standards/materiality-finder/find/?industry%5B0%5D=SV-AD
A10: Hostelería | B10: Matrice de materialidad | C10: MSCI: Restaurants | D10: https://www.msci.com/our-solutions/esg-investing/esg-industry-materiality-map
A11: Inmobilarias | B11: Matrice de materialidad | C11: SASB - Real Estate | D11: https://sasb.org/standards/materiality-finder/find/?industry%5B0%5D=IF-RE
A12: Inmobilarias | B12: Matrice de materialidad | C12: SASB - Real Estate Services | D12: https://sasb.org/standards/materiality-finder/find/?industry%5B0%5D=IF-RS
... A38: Venta y Reparación de Vehículos | B38: Matrice de materialidad | C38: SASB: Automobiles | D38: https://sasb.org/standards/materiality-finder/find/?industry%5B0%5D=TR-AU

Sheet Aliments i Begudes
D1: Indústria alimentària i de begudes | E1: Aquest grup d'activitats és la combinació de CNAE 10 (Indústria de l'alimentació) i CNAE 11 (Producció de begudes). L'enfocament es basa principalment en la fabricació de productes alimentaris i begudes processades. No obstant això, a causa de la importància de la cadena de valor per a la sostenibilitat d'aquestes activitats, es tindrà en compte com gestionar efectivament la sostenibilitat de la cadena de valor.
D3: Gestió sostenible de l'aigua | E3: Subministrament de matèries primeres / productes venuts | F3: Materials d'embalatge | G3: Qualitat de l'aire | H3: Emissions de GEH | I3: Gestió de residus i materials perillosos | J3: Biodiversitat i ecosistemes | K3: Seguretat química
B4: Descripció | C4: Medi ambient | D4: =HLOOKUP(D3,AUTO!$B$1:$AJ$2,2,FALSE) -> La gestió sostenible de l'aigua tracta d'assegurar que el consum i ús d'aquesta aigua per part de l'empresa estiguin alineats amb la capacitat de recuperar-se de l'ecosistema i no generin impactes negatius. Les necessitats de consumir aigua estan lligades al sector i a la ubicació de la planta. És important destacar que les empreses amb operacions en zones amb estrès hídric caldrà que avaluïn com fer una gestió sostenible dels recursos hídrics. Això inclou reduir el consum d'aigua, millorar la captura i reutilització de les aigües grises i millorar el tractament d'aigües residuals, entre d'altres. | E4: =HLOOKUP(E3,AUTO!$B$1:$AJ$2,2,FALSE) -> El subministrament de matèries primeres és un tema crucial per a la sostenibilitat d'aquells sectors molt intensius en materials. Aquí les empreses haurien d'avaluar oportunitats per a una adquisició de matèries de manera sostenible amb proveïdors confiables i certificats i estratègies de recuperació de material que es pugui recuperar com a matèria primera. Aquest tema pot ser important tant per a empreses que adquireixen matèries primeres com per a empreses que adquireixen prefabricats o productes. Un exemple és la cadena de subministrament d'empreses alimentàries, on és obligatori poder demostrar que el producte utilitzat no prové de zones amb alta deforestació. | F4: =HLOOKUP(F3,AUTO!$B$1:$AJ$2,2,FALSE) -> Els materials d'embalatge son part del dia a dia i en certs casos acaben a la natura. És important que el productor faci un exercici d'ecodisseny que asseguri el mínim ús de material i la màxima reciclabilitat. | G4: =HLOOKUP(G3,AUTO!$B$1:$AJ$2,2,FALSE) -> Les emissions de contaminants com el diòxid de sofre (SOx), el diòxid de nitrogen (NOx) i els Compostos Orgànics Volàtils (VOC), entre d'altres, poden tenir un impacte significatiu sobre la qualitat de l'aire. Una mala qualitat de l'aire pot tenir efectes negatius tant sobre el medi ambient com sobre la salut de les comunitats afectades. Per tant, les empreses que duen a terme operacions que produeixen emissions a l'aire han d'avaluar el seu impacte sobre la qualitat de l'aire mitjançant controls regulars duts a terme per l'autoritat ambiental competent. Les empreses podrien considerar la instal·lació de filtres i altres mesures destinades a reduir les emissions de contaminants atmosfèrics. | H4: =HLOOKUP(H3,AUTO!$B$1:$AJ$2,2,FALSE) -> Les emissions de gasos amb efecte d'hivernacle i les energies renovables són categories estretament vinculades amb el canvi climàtic. Les empreses amb una major petjada de carboni contribueixen en major mesura al canvi climàtic. Reduir els impactes relacionats amb aquest tema requereix una reducció de la petjada de carboni de l'empresa. Això requereix una transició envers fonts d'energia renovables i la implementació d'estratègies per assolir emissions netes zero. | I4: =HLOOKUP(I3,AUTO!$B$1:$AJ$2,2,FALSE) -> La gestió de residus perillosos i no perillosos és un àmbit en constant evolució normativa. L'adequada gestió de residus i materials perillosos és clau per reduir la contaminació causada per l'empresa o els productes que posa al mercat. Optimitzar el disseny i la producció i treballar paral·lelament a millorar la gestió de residus és clau per transicionar envers una economia circular que redueixi la necessitat d'explotació de nous recursos naturals. Per tant, les empreses que gestionen els seus residus i eviten la seva generació són més sostenibles i estan més alineades amb els principis de l'economia circular. | J4: =HLOOKUP(J3,AUTO!$B$1:$AJ$2,2,FALSE) -> Aquesta categoria se centra en els impactes de les operacions o els actius d'una empresa sobre ecosistemes i la seva biodiversitat. Les activitats amb potencials impactes significatius són aquelles vinculades amb canvis en l'ús del sòl per a exploració/explotació de recursos naturals, construcció, agricultura extensiva, etc. Els impactes poden produir pèrdua de biodiversitat, destrucció d'hàbitats, deforestació i pèrdua de serveis ecosistèmics bàsics. Les empreses haurien d'avaluar les seves dependències i impactes sobre el capital natural (natura), mitigar els riscos associats i fomentar un impacte positiu en totes les fases de la cadena de valor de l'empresa. | K4: =HLOOKUP(K3,AUTO!$B$1:$AJ$2,2,FALSE) -> Garantir la seguretat química és de gran importància per preservar els ecosistemes i protegir les comunitats properes a instal·lacions que empren substàncies químiques perilloses. Les empreses que comercialitzen productes que contenen substàncies químiques perilloses susceptibles d'entrar en contacte amb l'entorn natural o els usuaris d'aquests productes és essencial que prenguin totes les mesures necessàries per prevenir aquesta situació. Millorar la seguretat química pot implicar la recerca d'alternatives de materials per a l'ús en els seus productes, dissenyar productes de manera segura per prevenir fuites de substàncies i elaborar un pla de gestió de residus al final del cicle de vida del producte.
B5: Indicadors | D5: - Petjada hídrica total de l'empresa + Cadena de subministrament + Operacions directes + Distribució - Consum total d'aigua - Consum d'aigua per volum de negocis (€) - Consum d'aigua per producte (nombre o pes) - Consum d'aigua en àrees amb estrès hídric - Descàrrega total d'aigua - Descàrrega total d'aigua en àrees amb estrès hídric - % de reutilització de l'aigua | E5: - % d'ingredients adquirits amb certificació de sostenibilitat - % dels principals proveïdors auditats en temes de sostenibilitat - Emissions de CO2 per kg d'ingredient (abast 3) - Consum d'aigua per kg o litre d'ingredient - Hectàrea de conversió de la terra (per exemple, deforestació) - % pèrdues/malbaratament alimentari generades en relació amb l'entrada de productes - Costos estalviats per l'aprofitament dels productes enretirats que no han esdevingut pèrdues/malbaratament alimentaris | F5: - Reducció en pes/volum de materials d'embalatge - % de materials reciclats en embalatge - % de materials d'embalatge reciclables - Materials òrganics (en situacions on el reciclatge no és viable) | G5: - Emissions de SOx, NOx i Compostos Orgànics Volàtils (VOC) - Mesurament de la qualitat de l'aire interior - Emissions de NOx dels vehicles de transport a les ciutats | H5: - Petjada de carboni de l'empresa (abast 1, 2 i 3), incloent: + emissions relacionades amb els combustibles fòssils + emissions relacionades amb l'electricitat i el vapor adquirit + emissions de gasos refrigerants (recàrregues d'equips frigorífics) + Altres emissions vinculades amb els materials usats, viatges per a negocis, etc. - Capacitat per generar energia renovable - Canvis d'emissions i capacitat de renovables | I5: - Generació total de residus - Generació de residus perillosos - Generació de residus no perillosos - % de residus destinats a eliminació - % de residus destinats a reutilització o reciclatge - % de productes dissenyats segons principis d'ecodisseny - % de pèrdues/malbaratament alimentaris generades en relació amb el volum de negoci de l'organització - % generació de pèrdues/malbaratament alimentaris per procés | J5: - Àrea de conversió dels ecosistemes (per exemple: deforestació o conversió de bosc verge a cultius) + Generat per les operacions mateixes + Generat per la cadena de valor - Abundància mitjana d'espècies - Canvis en l'abundància mitjana d'espècies | K5: - % dels ingredients/materials que compleixen la legislació UE d'agroquímics o certificacions de sostenibilitat - % dels ingredients de fonts orgàniques - Reducció en l'ús d'agroquímics en la cadena de valor - Ús total (pes o volum) de químics identificats en els processos de producció - Reducció en l'ús de químics identificats en els processos de producció - % del personal que treballa amb químics que tenen la formació adequada
C6: Social | D6: Seguretat i qualitat del producte | E6: Oportunitats de nutrició i salut | F6: Salut i seguretat laboral | G6: Estàndards de treball en la cadena de valor | H6: Practiques de venda i etiquetatge | I6: Desenvolupament del capital humà
B7: Descripció | D7: =HLOOKUP(D6,AUTO!$B$1:$AJ$2,2,FALSE) -> La seguretat i qualitat són aspectes importants del producte, no només des d'una perspectiva econòmica, sinó també des d'una perspectiva de sostenibilitat. Falles de seguretat i/o qualitat del producte poden afectar negativament la salut o la seguretat dels usuaris, la qual cosa pot produir una varietat de riscos tant per a la reputació de l'empresa com legals. Algunes de les mesures que les empreses poden prendre per gestionar aquests riscos són dur a terme proves de productes i gestionar el contingut, els ingredients i els químics utilitzats en el producte. | E7: =HLOOKUP(E6,AUTO!$B$1:$AJ$2,2,FALSE) -> Particularment en la indústria alimentària i de begudes, les oportunitats relacionades amb la nutrició i la salut són fonamentals per proporcionar productes de més qualitat als consumidors. Des d'una perspectiva de sostenibilitat social, és crucial que les empreses aprofitin les oportunitats per oferir productes amb un major valor nutricional i beneficis per a la salut dels consumidors. Aquelles empreses que aprofiten aquestes oportunitats poden destacar en el mercat, la qual cosa al seu torn contribueix a la seva sostenibilitat econòmica. | F7: =HLOOKUP(F6,AUTO!$B$1:$AJ$2,2,FALSE) -> La salut i seguretat laboral hauria de ser una prioritat fonamental en qualsevol empresa. Totes les empreses han d'assegurar-se de proporcionar un entorn de treball segur i saludable per als seus empleats. Això és especialment crucial en aquelles empreses que duen a terme operacions perilloses o tenen el potencial d'afectar adversament la salut dels seus treballadors. Una de les mesures clau per assegurar la salut i seguretat dels empleats és designar un/a responsable de salut i seguretat la funció principal del qual consisteix a avaluar els riscos per als empleats i implementar mesures de mitigació corresponents. | G7: =HLOOKUP(G6,AUTO!$B$1:$AJ$2,2,FALSE) -> És crucial mantenir alts estàndards laborals i condicions de treball dignes per a tots els empleats en la cadena de valor. L'empresa s'ha d'assegurar que tots els seus proveïdors respectin els drets laborals i humans, la qual cosa inclou garantir una remuneració justa, horaris laborals adequats i la prohibició del treball forçós i el treball infantil. Per assegurar condicions laborals acceptables en tota la cadena de valor, l'empresa pot requerir el compliment d'un codi de conducta per part dels seus proveïdors i dur a terme auditories en alguns d'ells per verificar-ne el compliment. | H7: =HLOOKUP(H6,AUTO!$B$1:$AJ$2,2,FALSE) -> És essencial mantenir Bones Pràctiques en la venda i l'etiquetatge de productes per prevenir qualsevol pràctica enganyosa. Les pràctiques enganyoses poden portar els consumidors a triar un producte que no s'ajusti a les seves necessitats o requeriments. Per tant, per garantir Bones Pràctiques en la venda i l'etiquetatge, una empresa ha de gestionar la transparència de la informació relacionada amb els seus productes, operacions i cadenes de valor. A més, és fonamental proporcionar informació precisa i rellevant sobre els productes, sense ocultar desavantatges o altres tipus d'informació d'interès. | I7: =HLOOKUP(I6,AUTO!$B$1:$AJ$2,2,FALSE) -> El desenvolupament del capital humà pot ser un factor important per a empreses en sectors que requereixen coneixements o habilitats específiques. Les empreses que no inverteixen en el desenvolupament dels seus empleats poden perdre competitivitat en el mercat laboral, la qual cosa pot afectar la seva capacitat d'atreure i mantenir personal capacitat. Per assegurar la sostenibilitat social i econòmica en el futur, l'empresa pot oferir oportunitats de creixement al seu personal. En la mateixa línia, per mantenir una posició competitiva al mercat, les empreses han d'invertir en la formació i educació dels seus empleats.
B8: Indicadors | D8: - Taxa de queixes sobre els productes - Taxa d'enretirades dels productes - Taxa de no-conformitats amb requisits de qualitat i/o seguretat - Taxa de contaminació per objectes estranys - Seguretat microbiològica - Gestió d'al·lèrgens - Vida útil del producte | E8: - Contingut de sucres, greixos i sal - Índex de nutrients crítics (vitamines, minerals i fibres) - Contingut nutricional beneficiós - Nombre de productes saludables - Percentatge de vendes de productes saludables - Compliment de l'etiquetatge nutricional - Inversió en recerca i desenvolupament en nutrició saludable | F8: - Taxa d'accidentalitat (per x empleats o per x hores treballades) - Índex de freqüència d'accidents (i canvis respecte d'altres anys) - Índex de gravetat d'accidents - Taxa de malalties laborals - Participació en formacions de seguretat - Taxa de compliment de procediments de seguretat - Nombre d'inspeccions de seguretat realitzades - Freqüència d'avaluació dels riscos laborals | G8: - % de compliment de proveïdors de les normatives laborals - % d'empleats amb contractes formals - Proveïdors certificats socialment (% valor dels contractes) - Participació dels proveïdors en iniciatives de responsabilitat social - Nombre de proveïdors auditats per condicions laborals - Ús d'equips de protecció personal - Disponibilitat d'assistència mèdica - Disponibilitat d'aigua potable i serveis sanitaris | H8: - % dels productes en venda que compleixen la legislació d'etiquetes - Nombre de denúncies de pràctiques de publicitat, venda o etiquetatge enganyosos - Nombre d'instàncies on l'empresa ha hagut d'adaptar la publicitat d'un producte per informació falsa | I8: - Hores de formació per empleat - % de promocions internes i de lideratge intern - Avaluació de l'acompliment personalitzat - Participació en programes de desenvolupament professional - Diversitat i inclusió (representació de minories) - % d'empleats amb plans de desenvolupament personalitzats - Taxa de retenció d'empleats
C9: Governança | D9: Bon govern | E9: Gestió de la cadena de subministrament
B10: Descripció | D10: =HLOOKUP(D9,AUTO!$B$1:$AJ$2,2,FALSE) -> El bon govern és un tema ampli, enfocat en la gestió responsable i ètica de l'organització en general. L'acompliment de bon govern està vinculat als codis ètics de l'empresa, l'estructura de la propietat i el control de l'empresa, la junta directiva (i la seva remuneració), una comptabilitat transparent, la política fiscal i la transparència. | E10: =HLOOKUP(E9,AUTO!$B$1:$AJ$2,2,FALSE) -> La gestió de les cadenes de subministrament és essencial per supervisar les externalitats ambientals i socials generades per les activitats dels proveïdors. Dins de les cadenes de valor, poden sorgir problemes relacionats amb la responsabilitat ambiental, els drets humans, les condicions laborals, l'ètica i la corrupció, entre altres aspectes. La gestió de les cadenes de subministrament pot implicar l'avaluació, selecció, seguiment i compromís amb els proveïdors amb l'objectiu de reduir i mitigar els impactes mediambientals i socials.
B11: Indicadors | D11: - Composició de la junta directiva - % de membres independents dins la junta directiva - Existència de canals de denúncies i protecció de les parts interessades involucrades - % de denúncies investigades - Compliment de codis (ètic, conducta, etc.) i normatives - % dels empleats (incloent-hi la junta directiva) amb remuneració basada en acompliment de sostenibilitat - Auditories i certificacions independents | E11: - % de proveïdors principals (valor de contractes) avaluats en temes de sostenibilitat - Petjada de carboni de la cadena de subministrament - % d'energia renovable en la cadena de subministrament - Reducció de residus i reciclatge dins de la cadena de subministrament (ecodisseny, embalatge, programes de retorn) - Certificació mediambiental i social de proveïdors - Compliment dels drets laborals - Avaluació del cicle de vida de productes - % generació de pèrdues/malbaratament alimentaris per causa de generació vinculada a processos externs (transport, proveïdor, altres)
B13: Mesures de gestió generals
B14: Tema | C14: Aplica a | D14: Descripció | E14: Font
B15: Bon govern - conducta de negocis | C15: Totes | D15: Comptar amb un codi de conducta que estableixi normes per a tots els empleats. Aquest document s'haurà d'alinear amb les normatives vigents per al sector, incloent especialment temes ambientals (contaminació de l'aire, aigua, sòl, impactes sobre la biodiversitat, emissions GEH, etc.), drets humans, condicions laborals, seguretat, anticorrupció i suborn, promoció de la igualtat (de gènere) i la inclusió de tothom. | E15: Consulteu més informació sobre el codi de conducta
B16: Bon govern - control de qualitat | C16: Totes | D16: L'empresa ha d'establir un sistema de gestió i control de qualitat per a tots els serveis i productes oferts a fi d'assegurar la qualitat del producte i la seguretat per als clients. És una bona pràctica certificar aquest sistema de gestió amb una ISO9001. | E16: Vegeu informació sobre la ISO 9001
B17: Impactes ambientals - sistema de gestió ambiental | C17: Totes | D17: L'empresa ha d'establir un sistema de gestió mediambiental que permeti identificar i avaluar els impactes potencials i reals i els riscos i les oportunitats relacionats amb la sostenibilitat de l'empresa. Els marcs per desenvolupar un sistema de gestió mediambiental són l'EMAS de la Unió Europea i la ISO14001. | E17: Consulteu informació sobre EMAS
E18: Vegeu informació sobre la ISO 14001.
B19: General - estat d'informe no financer | C19: Totes | D19: Els requisits de divulgació d'informació no financera, especialment pel que fa a la sostenibilitat, estan guanyant rellevància tant per a inversors com per a organismes públics. Aquesta tendència es troba estretament vinculada amb les regulacions de la Unió Europea en el marc del Pla de finances sostenibles i el Pacte verd. Tant la Directiva d'informació corporativa sostenible (CSRD) com la Llei 11/2018 harmonitzen els requisits de divulgació per a les grans empreses. Aquestes i altres iniciatives estan generant un efecte dominó sobre les cadenes de valor i el sistema financer, la qual cosa està portant a una major demanda d'informació per part d'empreses de totes les mides. Per tant, la divulgació d'informació sobre sostenibilitat reforça la posició d'una empresa en el mercat. Per a les petites i mitjanes empreses (PIME) que volen començar a divulgar informació no financera, el marc de referència GRI pot servir com a base. | E19: Consulteu més informació sobre la CSRD
E20: Consulteu la Llei 11/2018
E21: Consulteu més informació sobre el marc GRI
B22: Medi ambient - eficiència energètica | C22: Totes | D22: L'eficiència energètica exerceix un paper fonamental en la reducció de les emissions de gasos amb efecte d'hivernacle de qualsevol empresa. Millorar l'eficiència energètica permet a una empresa generar valor amb un menor ús de recursos escassos. El document BREF de la Unió Europea proporciona orientació específica per assolir un ús eficient dels recursos i l'energia en diversos sectors i promou l'adopció de pràctiques sostenibles i alineades amb els objectius de la UE. Això no només beneficia la sostenibilitat econòmica de l'empresa, sinó que també contribueix a combatre el canvi climàtic. | E22: Consulteu el Document de referència sobre les millors tecnologies disponibles en termes d'eficiència energètica
B23: Protecció de dades - política de protecció de dades | C23: Totes | D23: L'empresa ha d'establir una política de protecció de dades, alineades amb la llei de protecció de dades de la UE. Tot el personal ha de rebre formació per gestionar dades del client de manera adequada i hi ha d'haver un protocol de contigència per a casos d'emergència. Adjunt a la columna de fonts trobareu un exemple d'una política de protecció de dades de l'Agència Catalana de Turisme. | E23: Consulteu un exemple d'una política de protecció de dades
B24: Bon govern - conducta de proveïdors | C24: Totes | D24: L'empresa ha d'establir un codi de conducta per als seus proveïdors i altres actors en la cadena de valor del negoci. Aquest codi ha de ser signat pels proveïdors i exigir-ne el compliment amb els estàndards de bon govern establerts en el document. Es recomana alinear aquest codi de conducta amb el codi de conducta intern, encara que en certs casos es pot permetre certa flexibilitat, sempre que continuï estant de conformitat amb les regulacions vigents relacionades amb la cadena de valor, com aquelles relacionades amb la no deforestació, els drets humans o les emissions de carboni, entre d'altres. A la columna 'Fonts' adjunta, trobareu un exemple d'un codi de conducta/ètic per a proveïdors del Pacte Mundial de Nacions Unides. | E24: Consulteu un exemple de codi de conducta/ètica de proveïdors
B25: Social - Pla d'igualtat de gènere | C25: Empreses amb més de 50 treballadors | D25: L'empresa ha d'implementar un pla d'igualtat de gènere en compliment del Reial decret 901/2020. Aquest requisit implica que les empreses han d'adoptar, amb negociació prèvia, mesures destinades a prevenir qualsevol forma de discriminació laboral entre dones i homes i a fomentar condicions de treball que evitin l'assetjament sexual i l'assetjament per raó de gènere. A més, han d'establir procediments específics per a la prevenció d'aquests comportaments i per gestionar les denúncies o reclamacions presentades per qui n'hagi estat víctima. | E25: Consulteu el Reial decret 901/2020
B26: Medi ambient - circularitat | C26: Totes | D26: Catalunya Circular és el hub d’innovació i punt de trobada d’empreses i institucions que aporten solucions i estratègies per consolidar l’economia circular a Catalunya. | E26: Consulta informació sobre Catalunya Circular, l'Observatori d'economia circular
E27: Consulteu més informació sobre l'economia circular (Fundació Ellen McArthur)
E28: Consulteu informació sobre el certificat Cradle to Cradle
B29: Medi ambient - residus | C29: Totes | D29: A partir de l'1 de gener de 2023, va entrar en vigor la Llei 7/2022, de 8 d'abril, de residus i sòls contaminats per una economia circular, que amplia la responsabilitat del productor de residus fins que aquests residus hagin estat gestionats per un gestor final. Això té implicacions per a totes les empreses que generen residus, ja que s'han d'assegurar que els residus siguin tractats o eliminats de manera adequada. A més, la Llei estableix que el productor de residus ha de fer separacions mínimes o garantir que un gestor les realitzi. També se li exigeix prioritzar la prevenció de la generació de residus per sobre de la reutilització, i aquesta per sobre del reciclatge, i aquest últim per sobre de l'eliminació. Finalment, s'han de donar prioritat als gestors ubicats geogràficament a prop. L'Agència de Residus de Catalunya té competència sobre els residus que es generen a Catalunya i els que es gestionen al seu àmbit territorial. Queden exclosos de la seva competència els residus radioactius, els residus resultants de la prospecció, l’extracció, el tractament i l’emmagatzematge de recursos minerals i de l’explotació de pedreres, els residus d’explotacions agrícoles i ramaderes que no siguin perillosos i s’utilitzin exclusivament en el marc de l’explotació agrària, els explosius desclassificats, les aigües residuals i els efluents gasosos emesos a l’atmosfera. | E29: Consulteu la Llei 7/2022
E30: Consulteu més informació sobre normativa catalana en matèria de residus
B31: Medi ambient - materials d'embalatge | C31: Totes | D31: Atès que la indústria manufacturera produeix productes físics, els materials d'embalatge utilitzats per al transport i la distribució d'aquests productes són un factor crucial amb un impacte potencialment significatiu. Per aquesta raó, la Unió Europea ha implementat una nova legislació que requereix la reducció de l'ús de plàstics d'un sol ús i en prohibeix certes aplicacions. A més, des de l'1 de gener, va entrar en vigor la Llei 7/2022, que estableix un nou impost sobre els envasos de plàstic no reutilitzables. Per tant, és important cercar materials d'embalatge que generin un menor impacte sobre el medi ambient, adaptats a l'aplicació i la ubicació geogràfica dels productes. La Sustainable Packaging Coalition ofereix diverses iniciatives destinades a ajudar les empreses a reduir l'impacte ambiental dels seus envasos. | E31: Consulteu informació sobre el Sustainable Packaging Coalition
E32: Consulteu informació sobre la Llei de plàstics d'un sol ús
E33: Consulteu informació sobre impostos sobre els envasos de plàstic no reutilitzables
B34: Medi ambient - compra sostenible | C34: La compra d'actius o productes | D34: Optar per actius o productes amb característiques d'eficiència i durabilitat contribueix a la reducció del consum de recursos i a la minimització de residus. Això no només té un impacte positiu sobre l'empremta ambiental, sinó que també pot generar estalvis operatius a llarg termini. Un exemple destacat és l'EU Ecolabel, una certificació ecològica reconeguda a la Unió Europea. Els productes que tenen aquesta etiqueta compleixen estàndards rigorosos de sostenibilitat en termes d'eficiència, materials i longevitat. En triar articles amb l'EU Ecolabel, les empreses poden demostrar el seu compromís amb pràctiques responsables i avançar cap a una operació més sostenible i respectuosa envers l'entorn. | E34: Consulteu informació sobre l'EU Ecolabel
B35: Medi ambient - Emissions de carboni | C35: Totes | D35: El transport de materials i productes contribueix al canvi climàtic a causa de les emissions de carboni que genera. Si bé és possible reduir la petjada de carboni en les activitats mateixes mitjançant l'ús d'energies renovables, el transport en si també té un impacte significatiu. Per aquesta raó, és important considerar formes de transport sostenible, com ara mitjans de transport respectuosos envers el medi ambient o la selecció de proveïdors locals, entre altres mesures. En el sector de la logística, hi ha iniciatives destinades a reduir les emissions d'aquest sector. Un exemple d'aquestes iniciatives és Lean and Green, que ajuda les empreses logístiques a reduir les seves emissions i compta amb un sistema de classificació basat en el seu acompliment. | E35: Consulteu informació sobre la iniciativa Lean and Green
E36: Consulteu informació sobre l'Oficina Catalana de Canvi Climàtic
